Workbook
Name sds: Tabular!$A$124:$D$124
Name ESFK: Tabular!$A$1:$C$1
Name skj: FacultyList!$A$1
Name twhrm: Tabular!$A$2

Sheet Tabular
A1: IF YOU FIND ANY MISMATCH, FOLLOW CONNECT.
A2: =IFERROR(__xludf.DUMMYFUNCTION("QUERY(IMPORTRANGE(Links!B7,""Theory_Distribute_Release!B:V""),""SELECT Col1, Col14, Col15, Col16, Col3, Col4, Col5, Col6, Col7, Col8, Col9 WHERE Col1 IS NOT NULL"",0)"),"Course") -> Course | B2: =IFERROR(__xludf.DUMMYFUNCTION("""COMPUTED_VALUE"""),"Theory Equivalent") -> Theory Equivalent | C2: =IFERROR(__xludf.DUMMYFUNCTION("""COMPUTED_VALUE"""),"Lab Equivalent") -> Lab Equivalent | D2: =IFERROR(__xludf.DUMMYFUNCTION("""COMPUTED_VALUE"""),"Theory Initial") -> Theory Initial | E2: =IFERROR(__xludf.DUMMYFUNCTION("""COMPUTED_VALUE"""),"Theory Day") -> Theory Day | F2: =IFERROR(__xludf.DUMMYFUNCTION("""COMPUTED_VALUE"""),"Theory Time (1hr 20min)") -> Theory Time (1hr 20min) | G2: =IFERROR(__xludf.DUMMYFUNCTION("""COMPUTED_VALUE"""),"Theory Room") -> Theory Room | H2: =IFERROR(__xludf.DUMMYFUNCTION("""COMPUTED_VALUE"""),"Lab Faculty") -> Lab Faculty | I2: =IFERROR(__xludf.DUMMYFUNCTION("""COMPUTED_VALUE"""),"Lab Day") -> Lab Day | J2: =IFERROR(__xludf.DUMMYFUNCTION("""COMPUTED_VALUE"""),"Lab Time (3hr)") -> Lab Time (3hr) | K2: =IFERROR(__xludf.DUMMYFUNCTION("""COMPUTED_VALUE"""),"Lab Room") -> Lab Room
A3: =IFERROR(__xludf.DUMMYFUNCTION("""COMPUTED_VALUE"""),"CSE101-01") -> CSE101-01 | D3: =IFERROR(__xludf.DUMMYFUNCTION("""COMPUTED_VALUE"""),"NZRF") -> NZRF | E3: =IFERROR(__xludf.DUMMYFUNCTION("""COMPUTED_VALUE"""),"MON+WED") -> MON+WED | F3: =IFERROR(__xludf.DUMMYFUNCTION("""COMPUTED_VALUE"""),"2:00 PM") -> 2:00 PM | G3: =IFERROR(__xludf.DUMMYFUNCTION("""COMPUTED_VALUE"""),"10B-13C") -> 10B-13C | H3: =IFERROR(__xludf.DUMMYFUNCTION("""COMPUTED_VALUE"""),"SBHN,CESF") -> SBHN,CESF | I3: =IFERROR(__xludf.DUMMYFUNCTION("""COMPUTED_VALUE"""),"SUN") -> SUN | J3: =IFERROR(__xludf.DUMMYFUNCTION("""COMPUTED_VALUE"""),"11:00 AM") -> 11:00 AM | K3: =IFERROR(__xludf.DUMMYFUNCTION("""COMPUTED_VALUE"""),"FT11-04L") -> FT11-04L | M3: =IFERROR(VLOOKUP(D3,FacultyList!B:G,6,FALSE),"") -> niaz.ashraf@bracu.ac.bd
A4: =IFERROR(__xludf.DUMMYFUNCTION("""COMPUTED_VALUE"""),"CSE101-02") -> CSE101-02 | D4: =IFERROR(__xludf.DUMMYFUNCTION("""COMPUTED_VALUE"""),"RBR") -> RBR | E4: =IFERROR(__xludf.DUMMYFUNCTION("""COMPUTED_VALUE"""),"MON+WED") -> MON+WED | F4: =IFERROR(__xludf.DUMMYFUNCTION("""COMPUTED_VALUE"""),"11:00 AM") -> 11:00 AM | G4: =IFERROR(__xludf.DUMMYFUNCTION("""COMPUTED_VALUE"""),"09D-17C") -> 09D-17C | H4: =IFERROR(__xludf.DUMMYFUNCTION("""COMPUTED_VALUE"""),"CESF,AQJ") -> CESF,AQJ | I4: =IFERROR(__xludf.DUMMYFUNCTION("""COMPUTED_VALUE"""),"TUE") -> TUE | J4: =IFERROR(__xludf.DUMMYFUNCTION("""COMPUTED_VALUE"""),"11:00 AM") -> 11:00 AM | K4: =IFERROR(__xludf.DUMMYFUNCTION("""COMPUTED_VALUE"""),"FT11-03L") -> FT11-03L | M4: =IFERROR(VLOOKUP(D4,FacultyList!B:G,6,FALSE),"") -> rakin.rabbani@bracu.ac.bd
A5: =IFERROR(__xludf.DUMMYFUNCTION("""COMPUTED_VALUE"""),"CSE101-03") -> CSE101-03 | D5: =IFERROR(__xludf.DUMMYFUNCTION("""COMPUTED_VALUE"""),"RBR") -> RBR | E5: =IFERROR(__xludf.DUMMYFUNCTION("""COMPUTED_VALUE"""),"MON+WED") -> MON+WED | F5: =IFERROR(__xludf.DUMMYFUNCTION("""COMPUTED_VALUE"""),"12:30 PM") -> 12:30 PM | G5: =IFERROR(__xludf.DUMMYFUNCTION("""COMPUTED_VALUE"""),"09D-17C") -> 09D-17C | H5: =IFERROR(__xludf.DUMMYFUNCTION("""COMPUTED_VALUE"""),"SLAR,CQAE") -> SLAR,CQAE | I5: =IFERROR(__xludf.DUMMYFUNCTION("""COMPUTED_VALUE"""),"THU") -> THU | J5: =IFERROR(__xludf.DUMMYFUNCTION("""COMPUTED_VALUE"""),"2:00 PM") -> 2:00 PM | K5: =IFERROR(__xludf.DUMMYFUNCTION("""COMPUTED_VALUE"""),"FT11-04L") -> FT11-04L | M5: =IFERROR(VLOOKUP(D5,FacultyList!B:G,6,FALSE),"") -> rakin.rabbani@bracu.ac.bd
A6: =IFERROR(__xludf.DUMMYFUNCTION("""COMPUTED_VALUE"""),"CSE101-04") -> CSE101-04 | D6: =IFERROR(__xludf.DUMMYFUNCTION("""COMPUTED_VALUE"""),"SBHN") -> SBHN | E6: =IFERROR(__xludf.DUMMYFUNCTION("""COMPUTED_VALUE"""),"SUN+TUE") -> SUN+TUE | F6: =IFERROR(__xludf.DUMMYFUNCTION("""COMPUTED_VALUE"""),"2:00 PM") -> 2:00 PM | G6: =IFERROR(__xludf.DUMMYFUNCTION("""COMPUTED_VALUE"""),"09H-35C") -> 09H-35C | H6: =IFERROR(__xludf.DUMMYFUNCTION("""COMPUTED_VALUE"""),"RBR,TRZA") -> RBR,TRZA | I6: =IFERROR(__xludf.DUMMYFUNCTION("""COMPUTED_VALUE"""),"MON") -> MON | J6: =IFERROR(__xludf.DUMMYFUNCTION("""COMPUTED_VALUE"""),"2:00 PM") -> 2:00 PM | K6: =IFERROR(__xludf.DUMMYFUNCTION("""COMPUTED_VALUE"""),"FT11-04L") -> FT11-04L | M6: =IFERROR(VLOOKUP(D6,FacultyList!B:G,6,FALSE),"") -> sabbir.hossain@bracu.ac.bd
A7: =IFERROR(__xludf.DUMMYFUNCTION("""COMPUTED_VALUE"""),"CSE101-05") -> CSE101-05 | D7: =IFERROR(__xludf.DUMMYFUNCTION("""COMPUTED_VALUE"""),"SBHN") -> SBHN | E7: =IFERROR(__xludf.DUMMYFUNCTION("""COMPUTED_VALUE"""),"SUN+TUE") -> SUN+TUE | F7: =IFERROR(__xludf.DUMMYFUNCTION("""COMPUTED_VALUE"""),"3:30 PM") -> 3:30 PM | G7: =IFERROR(__xludf.DUMMYFUNCTION("""COMPUTED_VALUE"""),"09H-35C") -> 09H-35C | H7: =IFERROR(__xludf.DUMMYFUNCTION("""COMPUTED_VALUE"""),"SBHN,SLAR") -> SBHN,SLAR | I7: =IFERROR(__xludf.DUMMYFUNCTION("""COMPUTED_VALUE"""),"WED") -> WED | J7: =IFERROR(__xludf.DUMMYFUNCTION("""COMPUTED_VALUE"""),"11:00 AM") -> 11:00 AM | K7: =IFERROR(__xludf.DUMMYFUNCTION("""COMPUTED_VALUE"""),"FT11-04L") -> FT11-04L | M7: =IFERROR(VLOOKUP(D7,FacultyList!B:G,6,FALSE),"") -> sabbir.hossain@bracu.ac.bd
A8: =IFERROR(__xludf.DUMMYFUNCTION("""COMPUTED_VALUE"""),"CSE101-06") -> CSE101-06 | D8: =IFERROR(__xludf.DUMMYFUNCTION("""COMPUTED_VALUE"""),"SBHN") -> SBHN | E8: =IFERROR(__xludf.DUMMYFUNCTION("""COMPUTED_VALUE"""),"MON+WED") -> MON+WED | F8: =IFERROR(__xludf.DUMMYFUNCTION("""COMPUTED_VALUE"""),"2:00 PM") -> 2:00 PM | G8: =IFERROR(__xludf.DUMMYFUNCTION("""COMPUTED_VALUE"""),"09D-17C") -> 09D-17C | H8: =IFERROR(__xludf.DUMMYFUNCTION("""COMPUTED_VALUE"""),"SLAR,CQAE") -> SLAR,CQAE | I8: =IFERROR(__xludf.DUMMYFUNCTION("""COMPUTED_VALUE"""),"SAT") -> SAT | J8: =IFERROR(__xludf.DUMMYFUNCTION("""COMPUTED_VALUE"""),"8:00 AM") -> 8:00 AM | K8: =IFERROR(__xludf.DUMMYFUNCTION("""COMPUTED_VALUE"""),"FT11-03L") -> FT11-03L | M8: =IFERROR(VLOOKUP(D8,FacultyList!B:G,6,FALSE),"") -> sabbir.hossain@bracu.ac.bd
A9: =IFERROR(__xludf.DUMMYFUNCTION("""COMPUTED_VALUE"""),"CSE103-01") -> CSE103-01 | D9: =IFERROR(__xludf.DUMMYFUNCTION("""COMPUTED_VALUE"""),"XXX") -> XXX | E9: =IFERROR(__xludf.DUMMYFUNCTION("""COMPUTED_VALUE"""),"XXX") -> XXX | F9: =IFERROR(__xludf.DUMMYFUNCTION("""COMPUTED_VALUE"""),"11:00 AM") -> 11:00 AM | G9: =IFERROR(__xludf.DUMMYFUNCTION("""COMPUTED_VALUE"""),"XXX") -> XXX | H9: =IFERROR(__xludf.DUMMYFUNCTION("""COMPUTED_VALUE"""),"FDM,SLAR") -> FDM,SLAR | I9: =IFERROR(__xludf.DUMMYFUNCTION("""COMPUTED_VALUE"""),"SAT") -> SAT | J9: =IFERROR(__xludf.DUMMYFUNCTION("""COMPUTED_VALUE"""),"2:00 PM") -> 2:00 PM | K9: =IFERROR(__xludf.DUMMYFUNCTION("""COMPUTED_VALUE"""),"11B-20L") -> 11B-20L | M9: =IFERROR(VLOOKUP(D9,FacultyList!B:G,6,FALSE),"")
A10: =IFERROR(__xludf.DUMMYFUNCTION("""COMPUTED_VALUE"""),"CSE110-01") -> CSE110-01 | D10: =IFERROR(__xludf.DUMMYFUNCTION("""COMPUTED_VALUE"""),"MSI") -> MSI | E10: =IFERROR(__xludf.DUMMYFUNCTION("""COMPUTED_VALUE"""),"MON+WED") -> MON+WED | F10: =IFERROR(__xludf.DUMMYFUNCTION("""COMPUTED_VALUE"""),"3:30 PM") -> 3:30 PM | G10: =IFERROR(__xludf.DUMMYFUNCTION("""COMPUTED_VALUE"""),"10A-04C") -> 10A-04C | H10: =IFERROR(__xludf.DUMMYFUNCTION("""COMPUTED_VALUE"""),"AOH,ANNH") -> AOH,ANNH | I10: =IFERROR(__xludf.DUMMYFUNCTION("""COMPUTED_VALUE"""),"THU") -> THU | J10: =IFERROR(__xludf.DUMMYFUNCTION("""COMPUTED_VALUE"""),"8:00 AM") -> 8:00 AM | K10: =IFERROR(__xludf.DUMMYFUNCTION("""COMPUTED_VALUE"""),"09B-08L") -> 09B-08L | M10: =IFERROR(VLOOKUP(D10,FacultyList!B:G,6,FALSE),"") -> md.saiful.islam@bracu.ac.bd
A11: =IFERROR(__xludf.DUMMYFUNCTION("""COMPUTED_VALUE"""),"CSE110-02") -> CSE110-02 | D11: =IFERROR(__xludf.DUMMYFUNCTION("""COMPUTED_VALUE"""),"MSI") -> MSI | E11: =IFERROR(__xludf.DUMMYFUNCTION("""COMPUTED_VALUE"""),"SUN+TUE") -> SUN+TUE | F11: =IFERROR(__xludf.DUMMYFUNCTION("""COMPUTED_VALUE"""),"11:00 AM") -> 11:00 AM | G11: =IFERROR(__xludf.DUMMYFUNCTION("""COMPUTED_VALUE"""),"10A-10C") -> 10A-10C | H11: =IFERROR(__xludf.DUMMYFUNCTION("""COMPUTED_VALUE"""),"MSI,SMUR") -> MSI,SMUR | I11: =IFERROR(__xludf.DUMMYFUNCTION("""COMPUTED_VALUE"""),"WED") -> WED | J11: =IFERROR(__xludf.DUMMYFUNCTION("""COMPUTED_VALUE"""),"8:00 AM") -> 8:00 AM | K11: =IFERROR(__xludf.DUMMYFUNCTION("""COMPUTED_VALUE"""),"09B-08L") -> 09B-08L | M11: =IFERROR(VLOOKUP(D11,FacultyList!B:G,6,FALSE),"") -> md.saiful.islam@bracu.ac.bd
A12: =IFERROR(__xludf.DUMMYFUNCTION("""COMPUTED_VALUE"""),"CSE110-03") -> CSE110-03 | D12: =IFERROR(__xludf.DUMMYFUNCTION("""COMPUTED_VALUE"""),"MSI") -> MSI | E12: =IFERROR(__xludf.DUMMYFUNCTION("""COMPUTED_VALUE"""),"SUN+TUE") -> SUN+TUE | F12: =IFERROR(__xludf.DUMMYFUNCTION("""COMPUTED_VALUE"""),"12:30 PM") -> 12:30 PM | G12: =IFERROR(__xludf.DUMMYFUNCTION("""COMPUTED_VALUE"""),"10A-10C") -> 10A-10C | H12: =IFERROR(__xludf.DUMMYFUNCTION("""COMPUTED_VALUE"""),"SMUR,RKBM") -> SMUR,RKBM | I12: =IFERROR(__xludf.DUMMYFUNCTION("""COMPUTED_VALUE"""),"WED") -> WED | J12: =IFERROR(__xludf.DUMMYFUNCTION("""COMPUTED_VALUE"""),"11:00 AM") -> 11:00 AM | K12: =IFERROR(__xludf.DUMMYFUNCTION("""COMPUTED_VALUE"""),"09B-08L") -> 09B-08L | M12: =IFERROR(VLOOKUP(D12,FacultyList!B:G,6,FALSE),"") -> md.saiful.islam@bracu.ac.bd
A13: =IFERROR(__xludf.DUMMYFUNCTION("""COMPUTED_VALUE"""),"CSE110-04") -> CSE110-04 | D13: =IFERROR(__xludf.DUMMYFUNCTION("""COMPUTED_VALUE"""),"MSI") -> MSI | E13: =IFERROR(__xludf.DUMMYFUNCTION("""COMPUTED_VALUE"""),"SUN+TUE") -> SUN+TUE | F13: =IFERROR(__xludf.DUMMYFUNCTION("""COMPUTED_VALUE"""),"3:30 PM") -> 3:30 PM | G13: =IFERROR(__xludf.DUMMYFUNCTION("""COMPUTED_VALUE"""),"10A-10C") -> 10A-10C | H13: =IFERROR(__xludf.DUMMYFUNCTION("""COMPUTED_VALUE"""),"MSI,CAKM") -> MSI,CAKM | I13: =IFERROR(__xludf.DUMMYFUNCTION("""COMPUTED_VALUE"""),"WED") -> WED | J13: =IFERROR(__xludf.DUMMYFUNCTION("""COMPUTED_VALUE"""),"11:00 AM") -> 11:00 AM | K13: =IFERROR(__xludf.DUMMYFUNCTION("""COMPUTED_VALUE"""),"09B-10L") -> 09B-10L | M13: =IFERROR(VLOOKUP(D13,FacultyList!B:G,6,FALSE),"") -> md.saiful.islam@bracu.ac.bd
A14: =IFERROR(__xludf.DUMMYFUNCTION("""COMPUTED_VALUE"""),"CSE110-05") -> CSE110-05 | D14: =IFERROR(__xludf.DUMMYFUNCTION("""COMPUTED_VALUE"""),"TAW") -> TAW | E14: =IFERROR(__xludf.DUMMYFUNCTION("""COMPUTED_VALUE"""),"MON+WED") -> MON+WED | F14: =IFERROR(__xludf.DUMMYFUNCTION("""COMPUTED_VALUE"""),"11:00 AM") -> 11:00 AM | G14: =IFERROR(__xludf.DUMMYFUNCTION("""COMPUTED_VALUE"""),"10A-05C") -> 10A-05C | H14: =IFERROR(__xludf.DUMMYFUNCTION("""COMPUTED_VALUE"""),"MAF,AOH") -> MAF,AOH | I14: =IFERROR(__xludf.DUMMYFUNCTION("""COMPUTED_VALUE"""),"THU") -> THU | J14: =IFERROR(__xludf.DUMMYFUNCTION("""COMPUTED_VALUE"""),"11:00 AM") -> 11:00 AM | K14: =IFERROR(__xludf.DUMMYFUNCTION("""COMPUTED_VALUE"""),"09B-08L") -> 09B-08L | M14: =IFERROR(VLOOKUP(D14,FacultyList!B:G,6,FALSE),"") -> tawhid.anwar@bracu.ac.bd
A15: =IFERROR(__xludf.DUMMYFUNCTION("""COMPUTED_VALUE"""),"CSE110-06") -> CSE110-06 | D15: =IFERROR(__xludf.DUMMYFUNCTION("""COMPUTED_VALUE"""),"ADU") -> ADU | E15: =IFERROR(__xludf.DUMMYFUNCTION("""COMPUTED_VALUE"""),"SUN+TUE") -> SUN+TUE | F15: =IFERROR(__xludf.DUMMYFUNCTION("""COMPUTED_VALUE"""),"12:30 PM") -> 12:30 PM | G15: =IFERROR(__xludf.DUMMYFUNCTION("""COMPUTED_VALUE"""),"09H-33C") -> 09H-33C | H15: =IFERROR(__xludf.DUMMYFUNCTION("""COMPUTED_VALUE"""),"ANNH,MVH") -> ANNH,MVH | I15: =IFERROR(__xludf.DUMMYFUNCTION("""COMPUTED_VALUE"""),"WED") -> WED | J15: =IFERROR(__xludf.DUMMYFUNCTION("""COMPUTED_VALUE"""),"8:00 AM") -> 8:00 AM | K15: =IFERROR(__xludf.DUMMYFUNCTION("""COMPUTED_VALUE"""),"09B-09L") -> 09B-09L | M15: =IFERROR(VLOOKUP(D15,FacultyList!B:G,6,FALSE),"") -> ahmed.ruhan@bracu.ac.bd
A16: =IFERROR(__xludf.DUMMYFUNCTION("""COMPUTED_VALUE"""),"CSE110-07") -> CSE110-07 | D16: =IFERROR(__xludf.DUMMYFUNCTION("""COMPUTED_VALUE"""),"RAK") -> RAK | E16: =IFERROR(__xludf.DUMMYFUNCTION("""COMPUTED_VALUE"""),"SUN+TUE") -> SUN+TUE | F16: =IFERROR(__xludf.DUMMYFUNCTION("""COMPUTED_VALUE"""),"8:00 AM") -> 8:00 AM | G16: =IFERROR(__xludf.DUMMYFUNCTION("""COMPUTED_VALUE"""),"10A-05C") -> 10A-05C | H16: =IFERROR(__xludf.DUMMYFUNCTION("""COMPUTED_VALUE"""),"NQM,NTN") -> NQM,NTN | I16: =IFERROR(__xludf.DUMMYFUNCTION("""COMPUTED_VALUE"""),"THU") -> THU | J16: =IFERROR(__xludf.DUMMYFUNCTION("""COMPUTED_VALUE"""),"11:00 AM") -> 11:00 AM | K16: =IFERROR(__xludf.DUMMYFUNCTION("""COMPUTED_VALUE"""),"09B-09L") -> 09B-09L | M16: =IFERROR(VLOOKUP(D16,FacultyList!B:G,6,FALSE),"") -> rubayat.ahmed@bracu.ac.bd
A17: =IFERROR(__xludf.DUMMYFUNCTION("""COMPUTED_VALUE"""),"CSE110-08") -> CSE110-08 | D17: =IFERROR(__xludf.DUMMYFUNCTION("""COMPUTED_VALUE"""),"AOH") -> AOH | E17: =IFERROR(__xludf.DUMMYFUNCTION("""COMPUTED_VALUE"""),"SUN+TUE") -> SUN+TUE | F17: =IFERROR(__xludf.DUMMYFUNCTION("""COMPUTED_VALUE"""),"3:30 PM") -> 3:30 PM | G17: =IFERROR(__xludf.DUMMYFUNCTION("""COMPUTED_VALUE"""),"09A-07C") -> 09A-07C | H17: =IFERROR(__xludf.DUMMYFUNCTION("""COMPUTED_VALUE"""),"AFA,KNI") -> AFA,KNI | I17: =IFERROR(__xludf.DUMMYFUNCTION("""COMPUTED_VALUE"""),"WED") -> WED | J17: =IFERROR(__xludf.DUMMYFUNCTION("""COMPUTED_VALUE"""),"11:00 AM") -> 11:00 AM | K17: =IFERROR(__xludf.DUMMYFUNCTION("""COMPUTED_VALUE"""),"09B-09L") -> 09B-09L | M17: =IFERROR(VLOOKUP(D17,FacultyList!B:G,6,FALSE),"") -> ext.abu.hasme@bracu.ac.bd
A18: =IFERROR(__xludf.DUMMYFUNCTION("""COMPUTED_VALUE"""),"CSE110-09") -> CSE110-09 | D18: =IFERROR(__xludf.DUMMYFUNCTION("""COMPUTED_VALUE"""),"KNI") -> KNI | E18: =IFERROR(__xludf.DUMMYFUNCTION("""COMPUTED_VALUE"""),"MON+WED") -> MON+WED | F18: =IFERROR(__xludf.DUMMYFUNCTION("""COMPUTED_VALUE"""),"2:00 PM") -> 2:00 PM | G18: =IFERROR(__xludf.DUMMYFUNCTION("""COMPUTED_VALUE"""),"09H-34C") -> 09H-34C | H18: =IFERROR(__xludf.DUMMYFUNCTION("""COMPUTED_VALUE"""),"ANNH,CAYR") -> ANNH,CAYR | I18: =IFERROR(__xludf.DUMMYFUNCTION("""COMPUTED_VALUE"""),"THU") -> THU | J18: =IFERROR(__xludf.DUMMYFUNCTION("""COMPUTED_VALUE"""),"2:00 PM") -> 2:00 PM | K18: =IFERROR(__xludf.DUMMYFUNCTION("""COMPUTED_VALUE"""),"09B-08L") -> 09B-08L | M18: =IFERROR(VLOOKUP(D18,FacultyList!B:G,6,FALSE),"") -> nazia.iqbal@bracu.ac.bd
A19: =IFERROR(__xludf.DUMMYFUNCTION("""COMPUTED_VALUE"""),"CSE110-10") -> CSE110-10 | D19: =IFERROR(__xludf.DUMMYFUNCTION("""COMPUTED_VALUE"""),"KNI") -> KNI | E19: =IFERROR(__xludf.DUMMYFUNCTION("""COMPUTED_VALUE"""),"MON+WED") -> MON+WED | F19: =IFERROR(__xludf.DUMMYFUNCTION("""COMPUTED_VALUE"""),"3:30 PM") -> 3:30 PM | G19: =IFERROR(__xludf.DUMMYFUNCTION("""COMPUTED_VALUE"""),"09H-34C") -> 09H-34C | H19: =IFERROR(__xludf.DUMMYFUNCTION("""COMPUTED_VALUE"""),"WLV,ANT") -> WLV,ANT | I19: =IFERROR(__xludf.DUMMYFUNCTION("""COMPUTED_VALUE"""),"THU") -> THU | J19: =IFERROR(__xludf.DUMMYFUNCTION("""COMPUTED_VALUE"""),"8:00 AM") -> 8:00 AM | K19: =IFERROR(__xludf.DUMMYFUNCTION("""COMPUTED_VALUE"""),"09B-09L") -> 09B-09L | M19: =IFERROR(VLOOKUP(D19,FacultyList!B:G,6,FALSE),"") -> nazia.iqbal@bracu.ac.bd
A20: =IFERROR(__xludf.DUMMYFUNCTION("""COMPUTED_VALUE"""),"CSE110-11") -> CSE110-11 | D20: =IFERROR(__xludf.DUMMYFUNCTION("""COMPUTED_VALUE"""),"MAU") -> MAU | E20: =IFERROR(__xludf.DUMMYFUNCTION("""COMPUTED_VALUE"""),"SUN+TUE") -> SUN+TUE | F20: =IFERROR(__xludf.DUMMYFUNCTION("""COMPUTED_VALUE"""),"9:30 AM") -> 9:30 AM | G20: =IFERROR(__xludf.DUMMYFUNCTION("""COMPUTED_VALUE"""),"09A-03C") -> 09A-03C | H20: =IFERROR(__xludf.DUMMYFUNCTION("""COMPUTED_VALUE"""),"WLV,DFD") -> WLV,DFD | I20: =IFERROR(__xludf.DUMMYFUNCTION("""COMPUTED_VALUE"""),"THU") -> THU | J20: =IFERROR(__xludf.DUMMYFUNCTION("""COMPUTED_VALUE"""),"2:00 PM") -> 2:00 PM | K20: =IFERROR(__xludf.DUMMYFUNCTION("""COMPUTED_VALUE"""),"09B-09L") -> 09B-09L | M20: =IFERROR(VLOOKUP(D20,FacultyList!B:G,6,FALSE),"") -> marshia.nujhat@bracu.ac.bd
A21: =IFERROR(__xludf.DUMMYFUNCTION("""COMPUTED_VALUE"""),"CSE110-12") -> CSE110-12 | D21: =IFERROR(__xludf.DUMMYFUNCTION("""COMPUTED_VALUE"""),"ADU") -> ADU | E21: =IFERROR(__xludf.DUMMYFUNCTION("""COMPUTED_VALUE"""),"SUN+TUE") -> SUN+TUE | F21: =IFERROR(__xludf.DUMMYFUNCTION("""COMPUTED_VALUE"""),"11:00 AM") -> 11:00 AM | G21: =IFERROR(__xludf.DUMMYFUNCTION("""COMPUTED_VALUE"""),"09H-33C") -> 09H-33C | H21: =IFERROR(__xludf.DUMMYFUNCTION("""COMPUTED_VALUE"""),"CSAB,CAKM") -> CSAB,CAKM | I21: =IFERROR(__xludf.DUMMYFUNCTION("""COMPUTED_VALUE"""),"THU") -> THU | J21: =IFERROR(__xludf.DUMMYFUNCTION("""COMPUTED_VALUE"""),"2:00 PM") -> 2:00 PM | K21: =IFERROR(__xludf.DUMMYFUNCTION("""COMPUTED_VALUE"""),"09B-10L") -> 09B-10L | M21: =IFERROR(VLOOKUP(D21,FacultyList!B:G,6,FALSE),"") -> ahmed.ruhan@bracu.ac.bd
A22: =IFERROR(__xludf.DUMMYFUNCTION("""COMPUTED_VALUE"""),"CSE110-13") -> CSE110-13 | D22: =IFERROR(__xludf.DUMMYFUNCTION("""COMPUTED_VALUE"""),"MVH") -> MVH | E22: =IFERROR(__xludf.DUMMYFUNCTION("""COMPUTED_VALUE"""),"SAT+THU") -> SAT+THU | F22: =IFERROR(__xludf.DUMMYFUNCTION("""COMPUTED_VALUE"""),"11:00 AM") -> 11:00 AM | G22: =IFERROR(__xludf.DUMMYFUNCTION("""COMPUTED_VALUE"""),"07H-27C") -> 07H-27C | H22: =IFERROR(__xludf.DUMMYFUNCTION("""COMPUTED_VALUE"""),"NTN,RKBM") -> NTN,RKBM | I22: =IFERROR(__xludf.DUMMYFUNCTION("""COMPUTED_VALUE"""),"WED") -> WED | J22: =IFERROR(__xludf.DUMMYFUNCTION("""COMPUTED_VALUE"""),"8:00 AM") -> 8:00 AM | K22: =IFERROR(__xludf.DUMMYFUNCTION("""COMPUTED_VALUE"""),"09B-10L") -> 09B-10L | M22: =IFERROR(VLOOKUP(D22,FacultyList!B:G,6,FALSE),"") -> mohammad.naveed@bracu.ac.bd
A23: =IFERROR(__xludf.DUMMYFUNCTION("""COMPUTED_VALUE"""),"CSE110-14") -> CSE110-14 | D23: =IFERROR(__xludf.DUMMYFUNCTION("""COMPUTED_VALUE"""),"MVH") -> MVH | E23: =IFERROR(__xludf.DUMMYFUNCTION("""COMPUTED_VALUE"""),"SAT+THU") -> SAT+THU | F23: =IFERROR(__xludf.DUMMYFUNCTION("""COMPUTED_VALUE"""),"12:30 PM") -> 12:30 PM | G23: =IFERROR(__xludf.DUMMYFUNCTION("""COMPUTED_VALUE"""),"07H-27C") -> 07H-27C | H23: =IFERROR(__xludf.DUMMYFUNCTION("""COMPUTED_VALUE"""),"WLV,MVH") -> WLV,MVH | I23: =IFERROR(__xludf.DUMMYFUNCTION("""COMPUTED_VALUE"""),"WED") -> WED | J23: =IFERROR(__xludf.DUMMYFUNCTION("""COMPUTED_VALUE"""),"2:00 PM") -> 2:00 PM | K23: =IFERROR(__xludf.DUMMYFUNCTION("""COMPUTED_VALUE"""),"09B-09L") -> 09B-09L | M23: =IFERROR(VLOOKUP(D23,FacultyList!B:G,6,FALSE),"") -> mohammad.naveed@bracu.ac.bd
A24: =IFERROR(__xludf.DUMMYFUNCTION("""COMPUTED_VALUE"""),"CSE110-15") -> CSE110-15 | D24: =IFERROR(__xludf.DUMMYFUNCTION("""COMPUTED_VALUE"""),"ATY") -> ATY | E24: =IFERROR(__xludf.DUMMYFUNCTION("""COMPUTED_VALUE"""),"MON+WED") -> MON+WED | F24: =IFERROR(__xludf.DUMMYFUNCTION("""COMPUTED_VALUE"""),"12:30 PM") -> 12:30 PM | G24: =IFERROR(__xludf.DUMMYFUNCTION("""COMPUTED_VALUE"""),"09A-05C") -> 09A-05C | H24: =IFERROR(__xludf.DUMMYFUNCTION("""COMPUTED_VALUE"""),"CAKM,CSAB") -> CAKM,CSAB | I24: =IFERROR(__xludf.DUMMYFUNCTION("""COMPUTED_VALUE"""),"THU") -> THU | J24: =IFERROR(__xludf.DUMMYFUNCTION("""COMPUTED_VALUE"""),"8:00 AM") -> 8:00 AM | K24: =IFERROR(__xludf.DUMMYFUNCTION("""COMPUTED_VALUE"""),"09B-11L") -> 09B-11L | M24: =IFERROR(VLOOKUP(D24,FacultyList!B:G,6,FALSE),"") -> ateya.ahmed@bracu.ac.bd
A25: =IFERROR(__xludf.DUMMYFUNCTION("""COMPUTED_VALUE"""),"CSE110-16") -> CSE110-16 | D25: =IFERROR(__xludf.DUMMYFUNCTION("""COMPUTED_VALUE"""),"ANT") -> ANT | E25: =IFERROR(__xludf.DUMMYFUNCTION("""COMPUTED_VALUE"""),"MON+WED") -> MON+WED | F25: =IFERROR(__xludf.DUMMYFUNCTION("""COMPUTED_VALUE"""),"8:00 AM") -> 8:00 AM | G25: =IFERROR(__xludf.DUMMYFUNCTION("""COMPUTED_VALUE"""),"09H-34C") -> 09H-34C | H25: =IFERROR(__xludf.DUMMYFUNCTION("""COMPUTED_VALUE"""),"ANNH,SLAR") -> ANNH,SLAR | I25: =IFERROR(__xludf.DUMMYFUNCTION("""COMPUTED_VALUE"""),"THU") -> THU | J25: =IFERROR(__xludf.DUMMYFUNCTION("""COMPUTED_VALUE"""),"11:00 AM") -> 11:00 AM | K25: =IFERROR(__xludf.DUMMYFUNCTION("""COMPUTED_VALUE"""),"09B-11L") -> 09B-11L | M25: =IFERROR(VLOOKUP(D25,FacultyList!B:G,6,FALSE),"") -> ext.anika.tasnim@bracu.ac.bd
A26: =IFERROR(__xludf.DUMMYFUNCTION("""COMPUTED_VALUE"""),"CSE110-17") -> CSE110-17 | D26: =IFERROR(__xludf.DUMMYFUNCTION("""COMPUTED_VALUE"""),"YND") -> YND | E26: =IFERROR(__xludf.DUMMYFUNCTION("""COMPUTED_VALUE"""),"MON+WED") -> MON+WED | F26: =IFERROR(__xludf.DUMMYFUNCTION("""COMPUTED_VALUE"""),"11:00 AM") -> 11:00 AM | G26: =IFERROR(__xludf.DUMMYFUNCTION("""COMPUTED_VALUE"""),"09A-05C") -> 09A-05C | H26: =IFERROR(__xludf.DUMMYFUNCTION("""COMPUTED_VALUE"""),"ANV,CNFH") -> ANV,CNFH | I26: =IFERROR(__xludf.DUMMYFUNCTION("""COMPUTED_VALUE"""),"THU") -> THU | J26: =IFERROR(__xludf.DUMMYFUNCTION("""COMPUTED_VALUE"""),"11:00 AM") -> 11:00 AM | K26: =IFERROR(__xludf.DUMMYFUNCTION("""COMPUTED_VALUE"""),"09F-27L") -> 09F-27L | M26: =IFERROR(VLOOKUP(D26,FacultyList!B:G,6,FALSE),"") -> yasmin.nadia@bracu.ac.bd
A27: =IFERROR(__xludf.DUMMYFUNCTION("""COMPUTED_VALUE"""),"CSE111-01") -> CSE111-01 | D27: =IFERROR(__xludf.DUMMYFUNCTION("""COMPUTED_VALUE"""),"ANK") -> ANK | E27: =IFERROR(__xludf.DUMMYFUNCTION("""COMPUTED_VALUE"""),"MON+WED") -> MON+WED | F27: =IFERROR(__xludf.DUMMYFUNCTION("""COMPUTED_VALUE"""),"2:00 PM") -> 2:00 PM | G27: =IFERROR(__xludf.DUMMYFUNCTION("""COMPUTED_VALUE"""),"09H-33C") -> 09H-33C | H27: =IFERROR(__xludf.DUMMYFUNCTION("""COMPUTED_VALUE"""),"AIB,ATY") -> AIB,ATY | I27: =IFERROR(__xludf.DUMMYFUNCTION("""COMPUTED_VALUE"""),"TUE") -> TUE | J27: =IFERROR(__xludf.DUMMYFUNCTION("""COMPUTED_VALUE"""),"11:00 AM") -> 11:00 AM | K27: =IFERROR(__xludf.DUMMYFUNCTION("""COMPUTED_VALUE"""),"09B-08L") -> 09B-08L | M27: =IFERROR(VLOOKUP(D27,FacultyList!B:G,6,FALSE),"") -> abdullah.alnakib@bracu.ac.bd
A28: =IFERROR(__xludf.DUMMYFUNCTION("""COMPUTED_VALUE"""),"CSE111-02") -> CSE111-02 | D28: =IFERROR(__xludf.DUMMYFUNCTION("""COMPUTED_VALUE"""),"TAW") -> TAW | E28: =IFERROR(__xludf.DUMMYFUNCTION("""COMPUTED_VALUE"""),"SUN+TUE") -> SUN+TUE | F28: =IFERROR(__xludf.DUMMYFUNCTION("""COMPUTED_VALUE"""),"11:00 AM") -> 11:00 AM | G28: =IFERROR(__xludf.DUMMYFUNCTION("""COMPUTED_VALUE"""),"10A-05C") -> 10A-05C | H28: =IFERROR(__xludf.DUMMYFUNCTION("""COMPUTED_VALUE"""),"TAW,AOH") -> TAW,AOH | I28: =IFERROR(__xludf.DUMMYFUNCTION("""COMPUTED_VALUE"""),"WED") -> WED | J28: =IFERROR(__xludf.DUMMYFUNCTION("""COMPUTED_VALUE"""),"2:00 PM") -> 2:00 PM | K28: =IFERROR(__xludf.DUMMYFUNCTION("""COMPUTED_VALUE"""),"12F-32L") -> 12F-32L | M28: =IFERROR(VLOOKUP(D28,FacultyList!B:G,6,FALSE),"") -> tawhid.anwar@bracu.ac.bd
A29: =IFERROR(__xludf.DUMMYFUNCTION("""COMPUTED_VALUE"""),"CSE111-03") -> CSE111-03 | D29: =IFERROR(__xludf.DUMMYFUNCTION("""COMPUTED_VALUE"""),"TAW") -> TAW | E29: =IFERROR(__xludf.DUMMYFUNCTION("""COMPUTED_VALUE"""),"SUN+TUE") -> SUN+TUE | F29: =IFERROR(__xludf.DUMMYFUNCTION("""COMPUTED_VALUE"""),"12:30 PM") -> 12:30 PM | G29: =IFERROR(__xludf.DUMMYFUNCTION("""COMPUTED_VALUE"""),"10A-05C") -> 10A-05C | H29: =IFERROR(__xludf.DUMMYFUNCTION("""COMPUTED_VALUE"""),"CAKM,HBN") -> CAKM,HBN | I29: =IFERROR(__xludf.DUMMYFUNCTION("""COMPUTED_VALUE"""),"WED") -> WED | J29: =IFERROR(__xludf.DUMMYFUNCTION("""COMPUTED_VALUE"""),"2:00 PM") -> 2:00 PM | K29: =IFERROR(__xludf.DUMMYFUNCTION("""COMPUTED_VALUE"""),"12D-27L") -> 12D-27L | M29: =IFERROR(VLOOKUP(D29,FacultyList!B:G,6,FALSE),"") -> tawhid.anwar@bracu.ac.bd
A30: =IFERROR(__xludf.DUMMYFUNCTION("""COMPUTED_VALUE"""),"CSE111-04") -> CSE111-04 | D30: =IFERROR(__xludf.DUMMYFUNCTION("""COMPUTED_VALUE"""),"TAW") -> TAW | E30: =IFERROR(__xludf.DUMMYFUNCTION("""COMPUTED_VALUE"""),"MON+WED") -> MON+WED | F30: =IFERROR(__xludf.DUMMYFUNCTION("""COMPUTED_VALUE"""),"12:30 PM") -> 12:30 PM | G30: =IFERROR(__xludf.DUMMYFUNCTION("""COMPUTED_VALUE"""),"10A-05C") -> 10A-05C | H30: =IFERROR(__xludf.DUMMYFUNCTION("""COMPUTED_VALUE"""),"TAW,RKBM") -> TAW,RKBM | I30: =IFERROR(__xludf.DUMMYFUNCTION("""COMPUTED_VALUE"""),"THU") -> THU | J30: =IFERROR(__xludf.DUMMYFUNCTION("""COMPUTED_VALUE"""),"11:00 AM") -> 11:00 AM | K30: =IFERROR(__xludf.DUMMYFUNCTION("""COMPUTED_VALUE"""),"12F-32L") -> 12F-32L | M30: =IFERROR(VLOOKUP(D30,FacultyList!B:G,6,FALSE),"") -> tawhid.anwar@bracu.ac.bd
A31: =IFERROR(__xludf.DUMMYFUNCTION("""COMPUTED_VALUE"""),"CSE111-05") -> CSE111-05 | D31: =IFERROR(__xludf.DUMMYFUNCTION("""COMPUTED_VALUE"""),"ADU") -> ADU | E31: =IFERROR(__xludf.DUMMYFUNCTION("""COMPUTED_VALUE"""),"MON+WED") -> MON+WED | F31: =IFERROR(__xludf.DUMMYFUNCTION("""COMPUTED_VALUE"""),"8:00 AM") -> 8:00 AM | G31: =IFERROR(__xludf.DUMMYFUNCTION("""COMPUTED_VALUE"""),"10B-13C") -> 10B-13C | H31: =IFERROR(__xludf.DUMMYFUNCTION("""COMPUTED_VALUE"""),"HBN,AOH") -> HBN,AOH | I31: =IFERROR(__xludf.DUMMYFUNCTION("""COMPUTED_VALUE"""),"TUE") -> TUE | J31: =IFERROR(__xludf.DUMMYFUNCTION("""COMPUTED_VALUE"""),"8:00 AM") -> 8:00 AM | K31: =IFERROR(__xludf.DUMMYFUNCTION("""COMPUTED_VALUE"""),"09B-09L") -> 09B-09L | M31: =IFERROR(VLOOKUP(D31,FacultyList!B:G,6,FALSE),"") -> ahmed.ruhan@bracu.ac.bd
A32: =IFERROR(__xludf.DUMMYFUNCTION("""COMPUTED_VALUE"""),"CSE111-06") -> CSE111-06 | D32: =IFERROR(__xludf.DUMMYFUNCTION("""COMPUTED_VALUE"""),"ADU") -> ADU | E32: =IFERROR(__xludf.DUMMYFUNCTION("""COMPUTED_VALUE"""),"MON+WED") -> MON+WED | F32: =IFERROR(__xludf.DUMMYFUNCTION("""COMPUTED_VALUE"""),"9:30 AM") -> 9:30 AM | G32: =IFERROR(__xludf.DUMMYFUNCTION("""COMPUTED_VALUE"""),"10B-13C") -> 10B-13C | H32: =IFERROR(__xludf.DUMMYFUNCTION("""COMPUTED_VALUE"""),"FGZ,AVB") -> FGZ,AVB | I32: =IFERROR(__xludf.DUMMYFUNCTION("""COMPUTED_VALUE"""),"TUE") -> TUE | J32: =IFERROR(__xludf.DUMMYFUNCTION("""COMPUTED_VALUE"""),"11:00 AM") -> 11:00 AM | K32: =IFERROR(__xludf.DUMMYFUNCTION("""COMPUTED_VALUE"""),"09B-09L") -> 09B-09L | M32: =IFERROR(VLOOKUP(D32,FacultyList!B:G,6,FALSE),"") -> ahmed.ruhan@bracu.ac.bd
A33: =IFERROR(__xludf.DUMMYFUNCTION("""COMPUTED_VALUE"""),"CSE111-07") -> CSE111-07 | D33: =IFERROR(__xludf.DUMMYFUNCTION("""COMPUTED_VALUE"""),"RKBM") -> RKBM | E33: =IFERROR(__xludf.DUMMYFUNCTION("""COMPUTED_VALUE"""),"SUN+TUE") -> SUN+TUE | F33: =IFERROR(__xludf.DUMMYFUNCTION("""COMPUTED_VALUE"""),"2:00 PM") -> 2:00 PM | G33: =IFERROR(__xludf.DUMMYFUNCTION("""COMPUTED_VALUE"""),"08H-22C") -> 08H-22C | H33: =IFERROR(__xludf.DUMMYFUNCTION("""COMPUTED_VALUE"""),"AFA,CRHB") -> AFA,CRHB | I33: =IFERROR(__xludf.DUMMYFUNCTION("""COMPUTED_VALUE"""),"WED") -> WED | J33: =IFERROR(__xludf.DUMMYFUNCTION("""COMPUTED_VALUE"""),"2:00 PM") -> 2:00 PM | K33: =IFERROR(__xludf.DUMMYFUNCTION("""COMPUTED_VALUE"""),"09B-11L") -> 09B-11L | M33: =IFERROR(VLOOKUP(D33,FacultyList!B:G,6,FALSE),"") -> mohammad.rakibul@bracu.ac.bd
A34: =IFERROR(__xludf.DUMMYFUNCTION("""COMPUTED_VALUE"""),"CSE111-08") -> CSE111-08 | D34: =IFERROR(__xludf.DUMMYFUNCTION("""COMPUTED_VALUE"""),"KNI") -> KNI | E34: =IFERROR(__xludf.DUMMYFUNCTION("""COMPUTED_VALUE"""),"SUN+TUE") -> SUN+TUE | F34: =IFERROR(__xludf.DUMMYFUNCTION("""COMPUTED_VALUE"""),"11:00 AM") -> 11:00 AM | G34: =IFERROR(__xludf.DUMMYFUNCTION("""COMPUTED_VALUE"""),"08H-22C") -> 08H-22C | H34: =IFERROR(__xludf.DUMMYFUNCTION("""COMPUTED_VALUE"""),"TMD,ADU") -> TMD,ADU | I34: =IFERROR(__xludf.DUMMYFUNCTION("""COMPUTED_VALUE"""),"WED") -> WED | J34: =IFERROR(__xludf.DUMMYFUNCTION("""COMPUTED_VALUE"""),"11:00 AM") -> 11:00 AM | K34: =IFERROR(__xludf.DUMMYFUNCTION("""COMPUTED_VALUE"""),"09B-11L") -> 09B-11L | M34: =IFERROR(VLOOKUP(D34,FacultyList!B:G,6,FALSE),"") -> nazia.iqbal@bracu.ac.bd
A35: =IFERROR(__xludf.DUMMYFUNCTION("""COMPUTED_VALUE"""),"CSE111-09") -> CSE111-09 | D35: =IFERROR(__xludf.DUMMYFUNCTION("""COMPUTED_VALUE"""),"KNI") -> KNI | E35: =IFERROR(__xludf.DUMMYFUNCTION("""COMPUTED_VALUE"""),"SUN+TUE") -> SUN+TUE | F35: =IFERROR(__xludf.DUMMYFUNCTION("""COMPUTED_VALUE"""),"12:30 PM") -> 12:30 PM | G35: =IFERROR(__xludf.DUMMYFUNCTION("""COMPUTED_VALUE"""),"08H-22C") -> 08H-22C | H35: =IFERROR(__xludf.DUMMYFUNCTION("""COMPUTED_VALUE"""),"ANV,CNFH") -> ANV,CNFH | I35: =IFERROR(__xludf.DUMMYFUNCTION("""COMPUTED_VALUE"""),"TUE") -> TUE | J35: =IFERROR(__xludf.DUMMYFUNCTION("""COMPUTED_VALUE"""),"8:00 AM") -> 8:00 AM | K35: =IFERROR(__xludf.DUMMYFUNCTION("""COMPUTED_VALUE"""),"09B-08L") -> 09B-08L | M35: =IFERROR(VLOOKUP(D35,FacultyList!B:G,6,FALSE),"") -> nazia.iqbal@bracu.ac.bd
A36: =IFERROR(__xludf.DUMMYFUNCTION("""COMPUTED_VALUE"""),"CSE111-10") -> CSE111-10 | D36: =IFERROR(__xludf.DUMMYFUNCTION("""COMPUTED_VALUE"""),"AIB") -> AIB | E36: =IFERROR(__xludf.DUMMYFUNCTION("""COMPUTED_VALUE"""),"SUN+TUE") -> SUN+TUE | F36: =IFERROR(__xludf.DUMMYFUNCTION("""COMPUTED_VALUE"""),"8:00 AM") -> 8:00 AM | G36: =IFERROR(__xludf.DUMMYFUNCTION("""COMPUTED_VALUE"""),"10A-04C") -> 10A-04C | H36: =IFERROR(__xludf.DUMMYFUNCTION("""COMPUTED_VALUE"""),"AVB,QUZA") -> AVB,QUZA | I36: =IFERROR(__xludf.DUMMYFUNCTION("""COMPUTED_VALUE"""),"WED") -> WED | J36: =IFERROR(__xludf.DUMMYFUNCTION("""COMPUTED_VALUE"""),"8:00 AM") -> 8:00 AM | K36: =IFERROR(__xludf.DUMMYFUNCTION("""COMPUTED_VALUE"""),"09E-21L") -> 09E-21L | M36: =IFERROR(VLOOKUP(D36,FacultyList!B:G,6,FALSE),"") -> abu.ibrahim@bracu.ac.bd
A37: =IFERROR(__xludf.DUMMYFUNCTION("""COMPUTED_VALUE"""),"CSE111-11") -> CSE111-11 | D37: =IFERROR(__xludf.DUMMYFUNCTION("""COMPUTED_VALUE"""),"AIB") -> AIB | E37: =IFERROR(__xludf.DUMMYFUNCTION("""COMPUTED_VALUE"""),"SUN+TUE") -> SUN+TUE | F37: =IFERROR(__xludf.DUMMYFUNCTION("""COMPUTED_VALUE"""),"9:30 AM") -> 9:30 AM | G37: =IFERROR(__xludf.DUMMYFUNCTION("""COMPUTED_VALUE"""),"10A-04C") -> 10A-04C | H37: =IFERROR(__xludf.DUMMYFUNCTION("""COMPUTED_VALUE"""),"AVB,FEK") -> AVB,FEK | I37: =IFERROR(__xludf.DUMMYFUNCTION("""COMPUTED_VALUE"""),"WED") -> WED | J37: =IFERROR(__xludf.DUMMYFUNCTION("""COMPUTED_VALUE"""),"11:00 AM") -> 11:00 AM | K37: =IFERROR(__xludf.DUMMYFUNCTION("""COMPUTED_VALUE"""),"09E-21L") -> 09E-21L | M37: =IFERROR(VLOOKUP(D37,FacultyList!B:G,6,FALSE),"") -> abu.ibrahim@bracu.ac.bd
A38: =IFERROR(__xludf.DUMMYFUNCTION("""COMPUTED_VALUE"""),"CSE111-13") -> CSE111-13 | D38: =IFERROR(__xludf.DUMMYFUNCTION("""COMPUTED_VALUE"""),"RKBM") -> RKBM | E38: =IFERROR(__xludf.DUMMYFUNCTION("""COMPUTED_VALUE"""),"SUN+TUE") -> SUN+TUE | F38: =IFERROR(__xludf.DUMMYFUNCTION("""COMPUTED_VALUE"""),"3:30 PM") -> 3:30 PM | G38: =IFERROR(__xludf.DUMMYFUNCTION("""COMPUTED_VALUE"""),"08H-22C") -> 08H-22C | H38: =IFERROR(__xludf.DUMMYFUNCTION("""COMPUTED_VALUE"""),"ATY,CSSA") -> ATY,CSSA | I38: =IFERROR(__xludf.DUMMYFUNCTION("""COMPUTED_VALUE"""),"WED") -> WED | J38: =IFERROR(__xludf.DUMMYFUNCTION("""COMPUTED_VALUE"""),"2:00 PM") -> 2:00 PM | K38: =IFERROR(__xludf.DUMMYFUNCTION("""COMPUTED_VALUE"""),"09E-21L") -> 09E-21L | M38: =IFERROR(VLOOKUP(D38,FacultyList!B:G,6,FALSE),"") -> mohammad.rakibul@bracu.ac.bd
A39: =IFERROR(__xludf.DUMMYFUNCTION("""COMPUTED_VALUE"""),"CSE111-14") -> CSE111-14 | D39: =IFERROR(__xludf.DUMMYFUNCTION("""COMPUTED_VALUE"""),"AFA") -> AFA | E39: =IFERROR(__xludf.DUMMYFUNCTION("""COMPUTED_VALUE"""),"SAT+THU") -> SAT+THU | F39: =IFERROR(__xludf.DUMMYFUNCTION("""COMPUTED_VALUE"""),"11:00 AM") -> 11:00 AM | G39: =IFERROR(__xludf.DUMMYFUNCTION("""COMPUTED_VALUE"""),"09A-02C") -> 09A-02C | H39: =IFERROR(__xludf.DUMMYFUNCTION("""COMPUTED_VALUE"""),"CNFH,AOH") -> CNFH,AOH | I39: =IFERROR(__xludf.DUMMYFUNCTION("""COMPUTED_VALUE"""),"WED") -> WED | J39: =IFERROR(__xludf.DUMMYFUNCTION("""COMPUTED_VALUE"""),"8:00 AM") -> 8:00 AM | K39: =IFERROR(__xludf.DUMMYFUNCTION("""COMPUTED_VALUE"""),"09B-11L") -> 09B-11L | M39: =IFERROR(VLOOKUP(D39,FacultyList!B:G,6,FALSE),"") -> afroza.akther@bracu.ac.bd
A40: =IFERROR(__xludf.DUMMYFUNCTION("""COMPUTED_VALUE"""),"CSE111-15") -> CSE111-15 | D40: =IFERROR(__xludf.DUMMYFUNCTION("""COMPUTED_VALUE"""),"MAU") -> MAU | E40: =IFERROR(__xludf.DUMMYFUNCTION("""COMPUTED_VALUE"""),"MON+WED") -> MON+WED | F40: =IFERROR(__xludf.DUMMYFUNCTION("""COMPUTED_VALUE"""),"9:30 AM") -> 9:30 AM | G40: =IFERROR(__xludf.DUMMYFUNCTION("""COMPUTED_VALUE"""),"09A-03C") -> 09A-03C | H40: =IFERROR(__xludf.DUMMYFUNCTION("""COMPUTED_VALUE"""),"AFA,AVB") -> AFA,AVB | I40: =IFERROR(__xludf.DUMMYFUNCTION("""COMPUTED_VALUE"""),"TUE") -> TUE | J40: =IFERROR(__xludf.DUMMYFUNCTION("""COMPUTED_VALUE"""),"8:00 AM") -> 8:00 AM | K40: =IFERROR(__xludf.DUMMYFUNCTION("""COMPUTED_VALUE"""),"09B-10L") -> 09B-10L | M40: =IFERROR(VLOOKUP(D40,FacultyList!B:G,6,FALSE),"") -> marshia.nujhat@bracu.ac.bd
...

Sheet FacultyList
B1: Initial | C1: Name | D1: Designation | E1: Status | F1: Room | G1: Email
B2: TBA | C2: To Be Announced
B3: TBC | C3: To Be Announced (CSE)
B4: TBE | C4: To Be Announced (EEE)
A5: {=IF(ISBLANK(B5),,HYPERLINK("https://docs.google.com/spreadsheets/d/1aZ_8do2w3aA382MhZyJKG5amXZ6fpthJYoLsdM9x0gU/edit?gid="&XLOOKUP(B5,ID___!A:A,ID___!B:B,"")&"#gid="&XLOOKUP(B5,ID___!A:A,ID___!B:B,"")&"&range=A1:J1","Click"))} -> Click | B5: =IFERROR(__xludf.DUMMYFUNCTION("QUERY( IMPORTRANGE(Links!B8, ""Load!A5:T500""), ""SELECT Col19, Col12, Col15, Col16, Col17, Col13 WHERE Col4 > 1 AND Col1 IS NOT NULL ORDER BY Col20, Col19"", 0 )"),"AAR") -> AAR | C5: =IFERROR(__xludf.DUMMYFUNCTION("""COMPUTED_VALUE"""),"Mr. Annajiat Alim Rasel") -> Mr. Annajiat Alim Rasel | D5: =IFERROR(__xludf.DUMMYFUNCTION("""COMPUTED_VALUE"""),"Senior Lecturer") -> Senior Lecturer | E5: =IFERROR(__xludf.DUMMYFUNCTION("""COMPUTED_VALUE"""),"Full Time") -> Full Time | F5: =IFERROR(__xludf.DUMMYFUNCTION("""COMPUTED_VALUE"""),"4G20") -> 4G20 | G5: =IFERROR(__xludf.DUMMYFUNCTION("""COMPUTED_VALUE"""),"annajiat@bracu.ac.bd") -> annajiat@bracu.ac.bd
A6: {=IF(ISBLANK(B6),,HYPERLINK("https://docs.google.com/spreadsheets/d/1aZ_8do2w3aA382MhZyJKG5amXZ6fpthJYoLsdM9x0gU/edit?gid="&XLOOKUP(B6,ID___!A:A,ID___!B:B,"")&"#gid="&XLOOKUP(B6,ID___!A:A,ID___!B:B,"")&"&range=A1:J1","Click"))} -> Click | B6: =IFERROR(__xludf.DUMMYFUNCTION("""COMPUTED_VALUE"""),"ACH") -> ACH | C6: =IFERROR(__xludf.DUMMYFUNCTION("""COMPUTED_VALUE"""),"Dr. Amitabha Chakrabarty") -> Dr. Amitabha Chakrabarty | D6: =IFERROR(__xludf.DUMMYFUNCTION("""COMPUTED_VALUE"""),"Professor") -> Professor | E6: =IFERROR(__xludf.DUMMYFUNCTION("""COMPUTED_VALUE"""),"Full Time") -> Full Time | F6: =IFERROR(__xludf.DUMMYFUNCTION("""COMPUTED_VALUE"""),"4G25") -> 4G25 | G6: =IFERROR(__xludf.DUMMYFUNCTION("""COMPUTED_VALUE"""),"amitabha@bracu.ac.bd") -> amitabha@bracu.ac.bd
A7: {=IF(ISBLANK(B7),,HYPERLINK("https://docs.google.com/spreadsheets/d/1aZ_8do2w3aA382MhZyJKG5amXZ6fpthJYoLsdM9x0gU/edit?gid="&XLOOKUP(B7,ID___!A:A,ID___!B:B,"")&"#gid="&XLOOKUP(B7,ID___!A:A,ID___!B:B,"")&"&range=A1:J1","Click"))} -> Click | B7: =IFERROR(__xludf.DUMMYFUNCTION("""COMPUTED_VALUE"""),"ADU") -> ADU | C7: =IFERROR(__xludf.DUMMYFUNCTION("""COMPUTED_VALUE"""),"Mr. Ahmed Mahir Ruhan") -> Mr. Ahmed Mahir Ruhan | D7: =IFERROR(__xludf.DUMMYFUNCTION("""COMPUTED_VALUE"""),"Lecturer") -> Lecturer | E7: =IFERROR(__xludf.DUMMYFUNCTION("""COMPUTED_VALUE"""),"Full Time") -> Full Time | F7: =IFERROR(__xludf.DUMMYFUNCTION("""COMPUTED_VALUE"""),"4L93") -> 4L93 | G7: =IFERROR(__xludf.DUMMYFUNCTION("""COMPUTED_VALUE"""),"ahmed.ruhan@bracu.ac.bd") -> ahmed.ruhan@bracu.ac.bd
A8: {=IF(ISBLANK(B8),,HYPERLINK("https://docs.google.com/spreadsheets/d/1aZ_8do2w3aA382MhZyJKG5amXZ6fpthJYoLsdM9x0gU/edit?gid="&XLOOKUP(B8,ID___!A:A,ID___!B:B,"")&"#gid="&XLOOKUP(B8,ID___!A:A,ID___!B:B,"")&"&range=A1:J1","Click"))} -> Click | B8: =IFERROR(__xludf.DUMMYFUNCTION("""COMPUTED_VALUE"""),"AFA") -> AFA | C8: =IFERROR(__xludf.DUMMYFUNCTION("""COMPUTED_VALUE"""),"Afroza Akhter") -> Afroza Akhter | D8: =IFERROR(__xludf.DUMMYFUNCTION("""COMPUTED_VALUE"""),"Lecturer") -> Lecturer | E8: =IFERROR(__xludf.DUMMYFUNCTION("""COMPUTED_VALUE"""),"Full Time") -> Full Time | F8: =IFERROR(__xludf.DUMMYFUNCTION("""COMPUTED_VALUE"""),"4K79") -> 4K79 | G8: =IFERROR(__xludf.DUMMYFUNCTION("""COMPUTED_VALUE"""),"afroza.akther@bracu.ac.bd") -> afroza.akther@bracu.ac.bd
A9: {=IF(ISBLANK(B9),,HYPERLINK("https://docs.google.com/spreadsheets/d/1aZ_8do2w3aA382MhZyJKG5amXZ6fpthJYoLsdM9x0gU/edit?gid="&XLOOKUP(B9,ID___!A:A,ID___!B:B,"")&"#gid="&XLOOKUP(B9,ID___!A:A,ID___!B:B,"")&"&range=A1:J1","Click"))} -> Click | B9: =IFERROR(__xludf.DUMMYFUNCTION("""COMPUTED_VALUE"""),"AFQ") -> AFQ | C9: =IFERROR(__xludf.DUMMYFUNCTION("""COMPUTED_VALUE"""),"Mohammed Ashfaqul Haque") -> Mohammed Ashfaqul Haque | D9: =IFERROR(__xludf.DUMMYFUNCTION("""COMPUTED_VALUE"""),"Lecturer") -> Lecturer | E9: =IFERROR(__xludf.DUMMYFUNCTION("""COMPUTED_VALUE"""),"Full Time") -> Full Time | F9: =IFERROR(__xludf.DUMMYFUNCTION("""COMPUTED_VALUE"""),"4N137") -> 4N137 | G9: =IFERROR(__xludf.DUMMYFUNCTION("""COMPUTED_VALUE"""),"ashfaqul.haque@bracu.ac.bd") -> ashfaqul.haque@bracu.ac.bd
A10: {=IF(ISBLANK(B10),,HYPERLINK("https://docs.google.com/spreadsheets/d/1aZ_8do2w3aA382MhZyJKG5amXZ6fpthJYoLsdM9x0gU/edit?gid="&XLOOKUP(B10,ID___!A:A,ID___!B:B,"")&"#gid="&XLOOKUP(B10,ID___!A:A,ID___!B:B,"")&"&range=A1:J1","Click"))} -> Click | B10: =IFERROR(__xludf.DUMMYFUNCTION("""COMPUTED_VALUE"""),"AIB") -> AIB | C10: =IFERROR(__xludf.DUMMYFUNCTION("""COMPUTED_VALUE"""),"Mr. Md. Abu Ibrahim") -> Mr. Md. Abu Ibrahim | D10: =IFERROR(__xludf.DUMMYFUNCTION("""COMPUTED_VALUE"""),"Lecturer") -> Lecturer | E10: =IFERROR(__xludf.DUMMYFUNCTION("""COMPUTED_VALUE"""),"Full Time") -> Full Time | F10: =IFERROR(__xludf.DUMMYFUNCTION("""COMPUTED_VALUE"""),"4J59") -> 4J59 | G10: =IFERROR(__xludf.DUMMYFUNCTION("""COMPUTED_VALUE"""),"abu.ibrahim@bracu.ac.bd") -> abu.ibrahim@bracu.ac.bd
A11: {=IF(ISBLANK(B11),,HYPERLINK("https://docs.google.com/spreadsheets/d/1aZ_8do2w3aA382MhZyJKG5amXZ6fpthJYoLsdM9x0gU/edit?gid="&XLOOKUP(B11,ID___!A:A,ID___!B:B,"")&"#gid="&XLOOKUP(B11,ID___!A:A,ID___!B:B,"")&"&range=A1:J1","Click"))} -> Click | B11: =IFERROR(__xludf.DUMMYFUNCTION("""COMPUTED_VALUE"""),"AJA") -> AJA | C11: =IFERROR(__xludf.DUMMYFUNCTION("""COMPUTED_VALUE"""),"Mr. Abid Jahan Apon") -> Mr. Abid Jahan Apon | D11: =IFERROR(__xludf.DUMMYFUNCTION("""COMPUTED_VALUE"""),"Lecturer") -> Lecturer | E11: =IFERROR(__xludf.DUMMYFUNCTION("""COMPUTED_VALUE"""),"Full Time") -> Full Time | F11: =IFERROR(__xludf.DUMMYFUNCTION("""COMPUTED_VALUE"""),"4M116") -> 4M116 | G11: =IFERROR(__xludf.DUMMYFUNCTION("""COMPUTED_VALUE"""),"abid.jahan@bracu.ac.bd") -> abid.jahan@bracu.ac.bd
A12: {=IF(ISBLANK(B12),,HYPERLINK("https://docs.google.com/spreadsheets/d/1aZ_8do2w3aA382MhZyJKG5amXZ6fpthJYoLsdM9x0gU/edit?gid="&XLOOKUP(B12,ID___!A:A,ID___!B:B,"")&"#gid="&XLOOKUP(B12,ID___!A:A,ID___!B:B,"")&"&range=A1:J1","Click"))} -> Click | B12: =IFERROR(__xludf.DUMMYFUNCTION("""COMPUTED_VALUE"""),"AKJ") -> AKJ | C12: =IFERROR(__xludf.DUMMYFUNCTION("""COMPUTED_VALUE"""),"Akib Anjum") -> Akib Anjum | D12: =IFERROR(__xludf.DUMMYFUNCTION("""COMPUTED_VALUE"""),"Lecturer") -> Lecturer | E12: =IFERROR(__xludf.DUMMYFUNCTION("""COMPUTED_VALUE"""),"Full Time") -> Full Time | F12: =IFERROR(__xludf.DUMMYFUNCTION("""COMPUTED_VALUE"""),"4N161") -> 4N161 | G12: =IFERROR(__xludf.DUMMYFUNCTION("""COMPUTED_VALUE"""),"anjum.akib@bracu.ac.bd") -> anjum.akib@bracu.ac.bd
A13: {=IF(ISBLANK(B13),,HYPERLINK("https://docs.google.com/spreadsheets/d/1aZ_8do2w3aA382MhZyJKG5amXZ6fpthJYoLsdM9x0gU/edit?gid="&XLOOKUP(B13,ID___!A:A,ID___!B:B,"")&"#gid="&XLOOKUP(B13,ID___!A:A,ID___!B:B,"")&"&range=A1:J1","Click"))} -> Click | B13: =IFERROR(__xludf.DUMMYFUNCTION("""COMPUTED_VALUE"""),"AKTD") -> AKTD | C13: =IFERROR(__xludf.DUMMYFUNCTION("""COMPUTED_VALUE"""),"Md. Akhtaruzaman Adnan") -> Md. Akhtaruzaman Adnan | D13: =IFERROR(__xludf.DUMMYFUNCTION("""COMPUTED_VALUE"""),"Senior Lecturer") -> Senior Lecturer | E13: =IFERROR(__xludf.DUMMYFUNCTION("""COMPUTED_VALUE"""),"Full Time") -> Full Time | F13: =IFERROR(__xludf.DUMMYFUNCTION("""COMPUTED_VALUE"""),"4G16") -> 4G16 | G13: =IFERROR(__xludf.DUMMYFUNCTION("""COMPUTED_VALUE"""),"akhtaruzzaman.adnan@bracu.ac.bd") -> akhtaruzzaman.adnan@bracu.ac.bd
A14: {=IF(ISBLANK(B14),,HYPERLINK("https://docs.google.com/spreadsheets/d/1aZ_8do2w3aA382MhZyJKG5amXZ6fpthJYoLsdM9x0gU/edit?gid="&XLOOKUP(B14,ID___!A:A,ID___!B:B,"")&"#gid="&XLOOKUP(B14,ID___!A:A,ID___!B:B,"")&"&range=A1:J1","Click"))} -> Click | B14: =IFERROR(__xludf.DUMMYFUNCTION("""COMPUTED_VALUE"""),"ALB") -> ALB | C14: =IFERROR(__xludf.DUMMYFUNCTION("""COMPUTED_VALUE"""),"Anindita Labonno") -> Anindita Labonno | D14: =IFERROR(__xludf.DUMMYFUNCTION("""COMPUTED_VALUE"""),"Lecturer") -> Lecturer | E14: =IFERROR(__xludf.DUMMYFUNCTION("""COMPUTED_VALUE"""),"Full Time") -> Full Time | F14: =IFERROR(__xludf.DUMMYFUNCTION("""COMPUTED_VALUE"""),"4L88") -> 4L88 | G14: =IFERROR(__xludf.DUMMYFUNCTION("""COMPUTED_VALUE"""),"anindita.labonno@bracu.ac.bd") -> anindita.labonno@bracu.ac.bd
A15: {=IF(ISBLANK(B15),,HYPERLINK("https://docs.google.com/spreadsheets/d/1aZ_8do2w3aA382MhZyJKG5amXZ6fpthJYoLsdM9x0gU/edit?gid="&XLOOKUP(B15,ID___!A:A,ID___!B:B,"")&"#gid="&XLOOKUP(B15,ID___!A:A,ID___!B:B,"")&"&range=A1:J1","Click"))} -> Click | B15: =IFERROR(__xludf.DUMMYFUNCTION("""COMPUTED_VALUE"""),"AMK") -> AMK | C15: =IFERROR(__xludf.DUMMYFUNCTION("""COMPUTED_VALUE"""),"Dr. Abu Mohammad Khan") -> Dr. Abu Mohammad Khan | D15: =IFERROR(__xludf.DUMMYFUNCTION("""COMPUTED_VALUE"""),"Associate Professor") -> Associate Professor | E15: =IFERROR(__xludf.DUMMYFUNCTION("""COMPUTED_VALUE"""),"Full Time") -> Full Time | F15: =IFERROR(__xludf.DUMMYFUNCTION("""COMPUTED_VALUE"""),"4G26") -> 4G26 | G15: =IFERROR(__xludf.DUMMYFUNCTION("""COMPUTED_VALUE"""),"abu.khan@bracu.ac.bd") -> abu.khan@bracu.ac.bd
A16: {=IF(ISBLANK(B16),,HYPERLINK("https://docs.google.com/spreadsheets/d/1aZ_8do2w3aA382MhZyJKG5amXZ6fpthJYoLsdM9x0gU/edit?gid="&XLOOKUP(B16,ID___!A:A,ID___!B:B,"")&"#gid="&XLOOKUP(B16,ID___!A:A,ID___!B:B,"")&"&range=A1:J1","Click"))} -> Click | B16: =IFERROR(__xludf.DUMMYFUNCTION("""COMPUTED_VALUE"""),"ANK") -> ANK | C16: =IFERROR(__xludf.DUMMYFUNCTION("""COMPUTED_VALUE"""),"Mr. Abdullah Al Nakib") -> Mr. Abdullah Al Nakib | D16: =IFERROR(__xludf.DUMMYFUNCTION("""COMPUTED_VALUE"""),"Lecturer") -> Lecturer | E16: =IFERROR(__xludf.DUMMYFUNCTION("""COMPUTED_VALUE"""),"Full Time") -> Full Time | F16: =IFERROR(__xludf.DUMMYFUNCTION("""COMPUTED_VALUE"""),"4J58") -> 4J58 | G16: =IFERROR(__xludf.DUMMYFUNCTION("""COMPUTED_VALUE"""),"abdullah.alnakib@bracu.ac.bd") -> abdullah.alnakib@bracu.ac.bd
A17: {=IF(ISBLANK(B17),,HYPERLINK("https://docs.google.com/spreadsheets/d/1aZ_8do2w3aA382MhZyJKG5amXZ6fpthJYoLsdM9x0gU/edit?gid="&XLOOKUP(B17,ID___!A:A,ID___!B:B,"")&"#gid="&XLOOKUP(B17,ID___!A:A,ID___!B:B,"")&"&range=A1:J1","Click"))} -> Click | B17: =IFERROR(__xludf.DUMMYFUNCTION("""COMPUTED_VALUE"""),"ANKH") -> ANKH | C17: =IFERROR(__xludf.DUMMYFUNCTION("""COMPUTED_VALUE"""),"Anika Ahmed") -> Anika Ahmed | D17: =IFERROR(__xludf.DUMMYFUNCTION("""COMPUTED_VALUE"""),"Lecturer") -> Lecturer | E17: =IFERROR(__xludf.DUMMYFUNCTION("""COMPUTED_VALUE"""),"Full Time") -> Full Time | F17: =IFERROR(__xludf.DUMMYFUNCTION("""COMPUTED_VALUE"""),"4K72") -> 4K72 | G17: =IFERROR(__xludf.DUMMYFUNCTION("""COMPUTED_VALUE"""),"anika.ahmed@bracu.ac.bd") -> anika.ahmed@bracu.ac.bd
A18: {=IF(ISBLANK(B18),,HYPERLINK("https://docs.google.com/spreadsheets/d/1aZ_8do2w3aA382MhZyJKG5amXZ6fpthJYoLsdM9x0gU/edit?gid="&XLOOKUP(B18,ID___!A:A,ID___!B:B,"")&"#gid="&XLOOKUP(B18,ID___!A:A,ID___!B:B,"")&"&range=A1:J1","Click"))} -> Click | B18: =IFERROR(__xludf.DUMMYFUNCTION("""COMPUTED_VALUE"""),"ANWE") -> ANWE | C18: =IFERROR(__xludf.DUMMYFUNCTION("""COMPUTED_VALUE"""),"Abdullah Nayem Wasi Emran") -> Abdullah Nayem Wasi Emran | D18: =IFERROR(__xludf.DUMMYFUNCTION("""COMPUTED_VALUE"""),"Lecturer") -> Lecturer | E18: =IFERROR(__xludf.DUMMYFUNCTION("""COMPUTED_VALUE"""),"Full Time") -> Full Time | F18: =IFERROR(__xludf.DUMMYFUNCTION("""COMPUTED_VALUE"""),"4N146") -> 4N146 | G18: =IFERROR(__xludf.DUMMYFUNCTION("""COMPUTED_VALUE"""),"abdullah.nayem@bracu.ac.bd") -> abdullah.nayem@bracu.ac.bd
A19: {=IF(ISBLANK(B19),,HYPERLINK("https://docs.google.com/spreadsheets/d/1aZ_8do2w3aA382MhZyJKG5amXZ6fpthJYoLsdM9x0gU/edit?gid="&XLOOKUP(B19,ID___!A:A,ID___!B:B,"")&"#gid="&XLOOKUP(B19,ID___!A:A,ID___!B:B,"")&"&range=A1:J1","Click"))} -> Click | B19: =IFERROR(__xludf.DUMMYFUNCTION("""COMPUTED_VALUE"""),"AQT") -> AQT | C19: =IFERROR(__xludf.DUMMYFUNCTION("""COMPUTED_VALUE"""),"Aniqa Tabassum") -> Aniqa Tabassum | D19: =IFERROR(__xludf.DUMMYFUNCTION("""COMPUTED_VALUE"""),"Lecturer") -> Lecturer | E19: =IFERROR(__xludf.DUMMYFUNCTION("""COMPUTED_VALUE"""),"Full Time") -> Full Time | F19: =IFERROR(__xludf.DUMMYFUNCTION("""COMPUTED_VALUE"""),"4N150") -> 4N150 | G19: =IFERROR(__xludf.DUMMYFUNCTION("""COMPUTED_VALUE"""),"aniqa.tabassum@bracu.ac.bd") -> aniqa.tabassum@bracu.ac.bd
A20: {=IF(ISBLANK(B20),,HYPERLINK("https://docs.google.com/spreadsheets/d/1aZ_8do2w3aA382MhZyJKG5amXZ6fpthJYoLsdM9x0gU/edit?gid="&XLOOKUP(B20,ID___!A:A,ID___!B:B,"")&"#gid="&XLOOKUP(B20,ID___!A:A,ID___!B:B,"")&"&range=A1:J1","Click"))} -> Click | B20: =IFERROR(__xludf.DUMMYFUNCTION("""COMPUTED_VALUE"""),"AQU") -> AQU | C20: =IFERROR(__xludf.DUMMYFUNCTION("""COMPUTED_VALUE"""),"Mr. Md. Aquib Azmain") -> Mr. Md. Aquib Azmain | D20: =IFERROR(__xludf.DUMMYFUNCTION("""COMPUTED_VALUE"""),"Senior Lecturer") -> Senior Lecturer | E20: =IFERROR(__xludf.DUMMYFUNCTION("""COMPUTED_VALUE"""),"Full Time") -> Full Time | F20: =IFERROR(__xludf.DUMMYFUNCTION("""COMPUTED_VALUE"""),"4M104") -> 4M104 | G20: =IFERROR(__xludf.DUMMYFUNCTION("""COMPUTED_VALUE"""),"aquib.azmain@bracu.ac.bd") -> aquib.azmain@bracu.ac.bd
A21: {=IF(ISBLANK(B21),,HYPERLINK("https://docs.google.com/spreadsheets/d/1aZ_8do2w3aA382MhZyJKG5amXZ6fpthJYoLsdM9x0gU/edit?gid="&XLOOKUP(B21,ID___!A:A,ID___!B:B,"")&"#gid="&XLOOKUP(B21,ID___!A:A,ID___!B:B,"")&"&range=A1:J1","Click"))} -> Click | B21: =IFERROR(__xludf.DUMMYFUNCTION("""COMPUTED_VALUE"""),"ARD") -> ARD | C21: =IFERROR(__xludf.DUMMYFUNCTION("""COMPUTED_VALUE"""),"Mr. Ayman Rasheed") -> Mr. Ayman Rasheed | D21: =IFERROR(__xludf.DUMMYFUNCTION("""COMPUTED_VALUE"""),"Lecturer") -> Lecturer | E21: =IFERROR(__xludf.DUMMYFUNCTION("""COMPUTED_VALUE"""),"Full Time") -> Full Time | F21: =IFERROR(__xludf.DUMMYFUNCTION("""COMPUTED_VALUE"""),"4M129") -> 4M129 | G21: =IFERROR(__xludf.DUMMYFUNCTION("""COMPUTED_VALUE"""),"ayman.rasheed@bracu.ac.bd") -> ayman.rasheed@bracu.ac.bd
A22: {=IF(ISBLANK(B22),,HYPERLINK("https://docs.google.com/spreadsheets/d/1aZ_8do2w3aA382MhZyJKG5amXZ6fpthJYoLsdM9x0gU/edit?gid="&XLOOKUP(B22,ID___!A:A,ID___!B:B,"")&"#gid="&XLOOKUP(B22,ID___!A:A,ID___!B:B,"")&"&range=A1:J1","Click"))} -> Click | B22: =IFERROR(__xludf.DUMMYFUNCTION("""COMPUTED_VALUE"""),"ARF") -> ARF | C22: =IFERROR(__xludf.DUMMYFUNCTION("""COMPUTED_VALUE"""),"Mr. Arif Shakil") -> Mr. Arif Shakil | D22: =IFERROR(__xludf.DUMMYFUNCTION("""COMPUTED_VALUE"""),"Senior Lecturer") -> Senior Lecturer | E22: =IFERROR(__xludf.DUMMYFUNCTION("""COMPUTED_VALUE"""),"Full Time") -> Full Time | F22: =IFERROR(__xludf.DUMMYFUNCTION("""COMPUTED_VALUE"""),"4G03") -> 4G03 | G22: =IFERROR(__xludf.DUMMYFUNCTION("""COMPUTED_VALUE"""),"arif.shakil@bracu.ac.bd") -> arif.shakil@bracu.ac.bd
A23: {=IF(ISBLANK(B23),,HYPERLINK("https://docs.google.com/spreadsheets/d/1aZ_8do2w3aA382MhZyJKG5amXZ6fpthJYoLsdM9x0gU/edit?gid="&XLOOKUP(B23,ID___!A:A,ID___!B:B,"")&"#gid="&XLOOKUP(B23,ID___!A:A,ID___!B:B,"")&"&range=A1:J1","Click"))} -> Click | B23: =IFERROR(__xludf.DUMMYFUNCTION("""COMPUTED_VALUE"""),"ART") -> ART | C23: =IFERROR(__xludf.DUMMYFUNCTION("""COMPUTED_VALUE"""),"Atanu Roy") -> Atanu Roy | D23: =IFERROR(__xludf.DUMMYFUNCTION("""COMPUTED_VALUE"""),"Lecturer") -> Lecturer | E23: =IFERROR(__xludf.DUMMYFUNCTION("""COMPUTED_VALUE"""),"Full Time") -> Full Time | F23: =IFERROR(__xludf.DUMMYFUNCTION("""COMPUTED_VALUE"""),"4M126") -> 4M126 | G23: =IFERROR(__xludf.DUMMYFUNCTION("""COMPUTED_VALUE"""),"atanu.roy@bracu.ac.bd") -> atanu.roy@bracu.ac.bd
A24: {=IF(ISBLANK(B24),,HYPERLINK("https://docs.google.com/spreadsheets/d/1aZ_8do2w3aA382MhZyJKG5amXZ6fpthJYoLsdM9x0gU/edit?gid="&XLOOKUP(B24,ID___!A:A,ID___!B:B,"")&"#gid="&XLOOKUP(B24,ID___!A:A,ID___!B:B,"")&"&range=A1:J1","Click"))} -> Click | B24: =IFERROR(__xludf.DUMMYFUNCTION("""COMPUTED_VALUE"""),"ASA") -> ASA | C24: =IFERROR(__xludf.DUMMYFUNCTION("""COMPUTED_VALUE"""),"Dr. Md. Ashraful Alam") -> Dr. Md. Ashraful Alam | D24: =IFERROR(__xludf.DUMMYFUNCTION("""COMPUTED_VALUE"""),"Associate Professor") -> Associate Professor | E24: =IFERROR(__xludf.DUMMYFUNCTION("""COMPUTED_VALUE"""),"Full Time") -> Full Time | F24: =IFERROR(__xludf.DUMMYFUNCTION("""COMPUTED_VALUE"""),"4G24") -> 4G24 | G24: =IFERROR(__xludf.DUMMYFUNCTION("""COMPUTED_VALUE"""),"ashraful.alam@bracu.ac.bd") -> ashraful.alam@bracu.ac.bd
A25: {=IF(ISBLANK(B25),,HYPERLINK("https://docs.google.com/spreadsheets/d/1aZ_8do2w3aA382MhZyJKG5amXZ6fpthJYoLsdM9x0gU/edit?gid="&XLOOKUP(B25,ID___!A:A,ID___!B:B,"")&"#gid="&XLOOKUP(B25,ID___!A:A,ID___!B:B,"")&"&range=A1:J1","Click"))} -> Click | B25: =IFERROR(__xludf.DUMMYFUNCTION("""COMPUTED_VALUE"""),"ASAK") -> ASAK | C25: =IFERROR(__xludf.DUMMYFUNCTION("""COMPUTED_VALUE"""),"Arnob Saha Ankon") -> Arnob Saha Ankon | D25: =IFERROR(__xludf.DUMMYFUNCTION("""COMPUTED_VALUE"""),"Lecturer") -> Lecturer | E25: =IFERROR(__xludf.DUMMYFUNCTION("""COMPUTED_VALUE"""),"Full Time") -> Full Time | F25: =IFERROR(__xludf.DUMMYFUNCTION("""COMPUTED_VALUE"""),"4M102") -> 4M102 | G25: =IFERROR(__xludf.DUMMYFUNCTION("""COMPUTED_VALUE"""),"arnob.ankon@bracu.ac.bd") -> arnob.ankon@bracu.ac.bd
A26: {=IF(ISBLANK(B26),,HYPERLINK("https://docs.google.com/spreadsheets/d/1aZ_8do2w3aA382MhZyJKG5amXZ6fpthJYoLsdM9x0gU/edit?gid="&XLOOKUP(B26,ID___!A:A,ID___!B:B,"")&"#gid="&XLOOKUP(B26,ID___!A:A,ID___!B:B,"")&"&range=A1:J1","Click"))} -> Click | B26: =IFERROR(__xludf.DUMMYFUNCTION("""COMPUTED_VALUE"""),"ASRF") -> ASRF | C26: =IFERROR(__xludf.DUMMYFUNCTION("""COMPUTED_VALUE"""),"Ashraful Islam Shanto Sikder") -> Ashraful Islam Shanto Sikder | D26: =IFERROR(__xludf.DUMMYFUNCTION("""COMPUTED_VALUE"""),"Lecturer") -> Lecturer | E26: =IFERROR(__xludf.DUMMYFUNCTION("""COMPUTED_VALUE"""),"Full Time") -> Full Time | F26: =IFERROR(__xludf.DUMMYFUNCTION("""COMPUTED_VALUE"""),"4P173") -> 4P173 | G26: =IFERROR(__xludf.DUMMYFUNCTION("""COMPUTED_VALUE"""),"ashraful.islam@bracu.ac.bd") -> ashraful.islam@bracu.ac.bd
A27: {=IF(ISBLANK(B27),,HYPERLINK("https://docs.google.com/spreadsheets/d/1aZ_8do2w3aA382MhZyJKG5amXZ6fpthJYoLsdM9x0gU/edit?gid="&XLOOKUP(B27,ID___!A:A,ID___!B:B,"")&"#gid="&XLOOKUP(B27,ID___!A:A,ID___!B:B,"")&"&range=A1:J1","Click"))} -> Click | B27: =IFERROR(__xludf.DUMMYFUNCTION("""COMPUTED_VALUE"""),"ATY") -> ATY | C27: =IFERROR(__xludf.DUMMYFUNCTION("""COMPUTED_VALUE"""),"Ateya Ahmed Subarna") -> Ateya Ahmed Subarna | D27: =IFERROR(__xludf.DUMMYFUNCTION("""COMPUTED_VALUE"""),"Lecturer") -> Lecturer | E27: =IFERROR(__xludf.DUMMYFUNCTION("""COMPUTED_VALUE"""),"Full Time") -> Full Time | F27: =IFERROR(__xludf.DUMMYFUNCTION("""COMPUTED_VALUE"""),"4K77") -> 4K77 | G27: =IFERROR(__xludf.DUMMYFUNCTION("""COMPUTED_VALUE"""),"ateya.ahmed@bracu.ac.bd") -> ateya.ahmed@bracu.ac.bd
A28: {=IF(ISBLANK(B28),,HYPERLINK("https://docs.google.com/spreadsheets/d/1aZ_8do2w3aA382MhZyJKG5amXZ6fpthJYoLsdM9x0gU/edit?gid="&XLOOKUP(B28,ID___!A:A,ID___!B:B,"")&"#gid="&XLOOKUP(B28,ID___!A:A,ID___!B:B,"")&"&range=A1:J1","Click"))} -> Click | B28: =IFERROR(__xludf.DUMMYFUNCTION("""COMPUTED_VALUE"""),"AVB") -> AVB | C28: =IFERROR(__xludf.DUMMYFUNCTION("""COMPUTED_VALUE"""),"Mr. Avinandan Banerjee") -> Mr. Avinandan Banerjee | D28: =IFERROR(__xludf.DUMMYFUNCTION("""COMPUTED_VALUE"""),"Lecturer") -> Lecturer | E28: =IFERROR(__xludf.DUMMYFUNCTION("""COMPUTED_VALUE"""),"Full Time") -> Full Time | F28: =IFERROR(__xludf.DUMMYFUNCTION("""COMPUTED_VALUE"""),"4M118") -> 4M118 | G28: =IFERROR(__xludf.DUMMYFUNCTION("""COMPUTED_VALUE"""),"avinandan@bracu.ac.bd") -> avinandan@bracu.ac.bd
A29: {=IF(ISBLANK(B29),,HYPERLINK("https://docs.google.com/spreadsheets/d/1aZ_8do2w3aA382MhZyJKG5amXZ6fpthJYoLsdM9x0gU/edit?gid="&XLOOKUP(B29,ID___!A:A,ID___!B:B,"")&"#gid="&XLOOKUP(B29,ID___!A:A,ID___!B:B,"")&"&range=A1:J1","Click"))} -> Click | B29: =IFERROR(__xludf.DUMMYFUNCTION("""COMPUTED_VALUE"""),"AYO") -> AYO | C29: =IFERROR(__xludf.DUMMYFUNCTION("""COMPUTED_VALUE"""),"Ariyan Hossain") -> Ariyan Hossain | D29: =IFERROR(__xludf.DUMMYFUNCTION("""COMPUTED_VALUE"""),"Lecturer") -> Lecturer | E29: =IFERROR(__xludf.DUMMYFUNCTION("""COMPUTED_VALUE"""),"Full Time") -> Full Time | F29: =IFERROR(__xludf.DUMMYFUNCTION("""COMPUTED_VALUE"""),"4N153") -> 4N153 | G29: =IFERROR(__xludf.DUMMYFUNCTION("""COMPUTED_VALUE"""),"ariyan.hossain@bracu.ac.bd") -> ariyan.hossain@bracu.ac.bd
A30: {=IF(ISBLANK(B30),,HYPERLINK("https://docs.google.com/spreadsheets/d/1aZ_8do2w3aA382MhZyJKG5amXZ6fpthJYoLsdM9x0gU/edit?gid="&XLOOKUP(B30,ID___!A:A,ID___!B:B,"")&"#gid="&XLOOKUP(B30,ID___!A:A,ID___!B:B,"")&"&range=A1:J1","Click"))} -> Click | B30: =IFERROR(__xludf.DUMMYFUNCTION("""COMPUTED_VALUE"""),"BDH") -> BDH | C30: =IFERROR(__xludf.DUMMYFUNCTION("""COMPUTED_VALUE"""),"Mr. Mohammad Badrul Hossain") -> Mr. Mohammad Badrul Hossain | D30: =IFERROR(__xludf.DUMMYFUNCTION("""COMPUTED_VALUE"""),"Lecturer") -> Lecturer | E30: =IFERROR(__xludf.DUMMYFUNCTION("""COMPUTED_VALUE"""),"Full Time") -> Full Time | F30: =IFERROR(__xludf.DUMMYFUNCTION("""COMPUTED_VALUE"""),"4J67") -> 4J67 | G30: =IFERROR(__xludf.DUMMYFUNCTION("""COMPUTED_VALUE"""),"badrul.hossain@bracu.ac.bd") -> badrul.hossain@bracu.ac.bd
A31: {=IF(ISBLANK(B31),,HYPERLINK("https://docs.google.com/spreadsheets/d/1aZ_8do2w3aA382MhZyJKG5amXZ6fpthJYoLsdM9x0gU/edit?gid="&XLOOKUP(B31,ID___!A:A,ID___!B:B,"")&"#gid="&XLOOKUP(B31,ID___!A:A,ID___!B:B,"")&"&range=A1:J1","Click"))} -> Click | B31: =IFERROR(__xludf.DUMMYFUNCTION("""COMPUTED_VALUE"""),"BIJS") -> BIJS | C31: =IFERROR(__xludf.DUMMYFUNCTION("""COMPUTED_VALUE"""),"Bijoy Ahmed Saiem") -> Bijoy Ahmed Saiem | D31: =IFERROR(__xludf.DUMMYFUNCTION("""COMPUTED_VALUE"""),"Lecturer") -> Lecturer | E31: =IFERROR(__xludf.DUMMYFUNCTION("""COMPUTED_VALUE"""),"Full Time") -> Full Time | F31: =IFERROR(__xludf.DUMMYFUNCTION("""COMPUTED_VALUE"""),"4M130") -> 4M130 | G31: =IFERROR(__xludf.DUMMYFUNCTION("""COMPUTED_VALUE"""),"bijoy.saiem@bracu.ac.bd") -> bijoy.saiem@bracu.ac.bd
A32: {=IF(ISBLANK(B32),,HYPERLINK("https://docs.google.com/spreadsheets/d/1aZ_8do2w3aA382MhZyJKG5amXZ6fpthJYoLsdM9x0gU/edit?gid="&XLOOKUP(B32,ID___!A:A,ID___!B:B,"")&"#gid="&XLOOKUP(B32,ID___!A:A,ID___!B:B,"")&"&range=A1:J1","Click"))} -> Click | B32: =IFERROR(__xludf.DUMMYFUNCTION("""COMPUTED_VALUE"""),"CMR") -> CMR | C32: =IFERROR(__xludf.DUMMYFUNCTION("""COMPUTED_VALUE"""),"Dr. Chowdhury Mofizur Rahman") -> Dr. Chowdhury Mofizur Rahman | D32: =IFERROR(__xludf.DUMMYFUNCTION("""COMPUTED_VALUE"""),"Professor") -> Professor | E32: =IFERROR(__xludf.DUMMYFUNCTION("""COMPUTED_VALUE"""),"Full Time") -> Full Time | F32: =IFERROR(__xludf.DUMMYFUNCTION("""COMPUTED_VALUE"""),"4G18") -> 4G18 | G32: =IFERROR(__xludf.DUMMYFUNCTION("""COMPUTED_VALUE"""),"rahman.mofizur@bracu.ac.bd") -> rahman.mofizur@bracu.ac.bd
A33: {=IF(ISBLANK(B33),,HYPERLINK("https://docs.google.com/spreadsheets/d/1aZ_8do2w3aA382MhZyJKG5amXZ6fpthJYoLsdM9x0gU/edit?gid="&XLOOKUP(B33,ID___!A:A,ID___!B:B,"")&"#gid="&XLOOKUP(B33,ID___!A:A,ID___!B:B,"")&"&range=A1:J1","Click"))} -> Click | B33: =IFERROR(__xludf.DUMMYFUNCTION("""COMPUTED_VALUE"""),"DFD") -> DFD | C33: =IFERROR(__xludf.DUMMYFUNCTION("""COMPUTED_VALUE"""),"Mr. Dibyo Fabian Dofadar") -> Mr. Dibyo Fabian Dofadar | D33: =IFERROR(__xludf.DUMMYFUNCTION("""COMPUTED_VALUE"""),"Lecturer") -> Lecturer | E33: =IFERROR(__xludf.DUMMYFUNCTION("""COMPUTED_VALUE"""),"Full Time") -> Full Time | F33: =IFERROR(__xludf.DUMMYFUNCTION("""COMPUTED_VALUE"""),"4M106") -> 4M106 | G33: =IFERROR(__xludf.DUMMYFUNCTION("""COMPUTED_VALUE"""),"fabian.dofadar@bracu.ac.bd") -> fabian.dofadar@bracu.ac.bd
A34: {=IF(ISBLANK(B34),,HYPERLINK("https://docs.google.com/spreadsheets/d/1aZ_8do2w3aA382MhZyJKG5amXZ6fpthJYoLsdM9x0gU/edit?gid="&XLOOKUP(B34,ID___!A:A,ID___!B:B,"")&"#gid="&XLOOKUP(B34,ID___!A:A,ID___!B:B,"")&"&range=A1:J1","Click"))} -> Click | B34: =IFERROR(__xludf.DUMMYFUNCTION("""COMPUTED_VALUE"""),"DPU") -> DPU | C34: =IFERROR(__xludf.DUMMYFUNCTION("""COMPUTED_VALUE"""),"Mr. Shoaib Ahmed Dipu") -> Mr. Shoaib Ahmed Dipu | D34: =IFERROR(__xludf.DUMMYFUNCTION("""COMPUTED_VALUE"""),"Lecturer") -> Lecturer | E34: =IFERROR(__xludf.DUMMYFUNCTION("""COMPUTED_VALUE"""),"Full Time") -> Full Time | F34: =IFERROR(__xludf.DUMMYFUNCTION("""COMPUTED_VALUE"""),"4J63") -> 4J63 | G34: =IFERROR(__xludf.DUMMYFUNCTION("""COMPUTED_VALUE"""),"shoaib.ahmed@bracu.ac.bd") -> shoaib.ahmed@bracu.ac.bd
A35: {=IF(ISBLANK(B35),,HYPERLINK("https://docs.google.com/spreadsheets/d/1aZ_8do2w3aA382MhZyJKG5amXZ6fpthJYoLsdM9x0gU/edit?gid="&XLOOKUP(B35,ID___!A:A,ID___!B:B,"")&"#gid="&XLOOKUP(B35,ID___!A:A,ID___!B:B,"")&"&range=A1:J1","Click"))} -> Click | B35: =IFERROR(__xludf.DUMMYFUNCTION("""COMPUTED_VALUE"""),"DZK") -> DZK | C35: =IFERROR(__xludf.DUMMYFUNCTION("""COMPUTED_VALUE"""),"Mr. Dewan Ziaul Karim") -> Mr. Dewan Ziaul Karim | D35: =IFERROR(__xludf.DUMMYFUNCTION("""COMPUTED_VALUE"""),"Senior Lecturer") -> Senior Lecturer | E35: =IFERROR(__xludf.DUMMYFUNCTION("""COMPUTED_VALUE"""),"Full Time") -> Full Time | F35: =IFERROR(__xludf.DUMMYFUNCTION("""COMPUTED_VALUE"""),"4G05") -> 4G05 | G35: =IFERROR(__xludf.DUMMYFUNCTION("""COMPUTED_VALUE"""),"ziaul.karim@bracu.ac.bd") -> ziaul.karim@bracu.ac.bd
A36: {=IF(ISBLANK(B36),,HYPERLINK("https://docs.google.com/spreadsheets/d/1aZ_8do2w3aA382MhZyJKG5amXZ6fpthJYoLsdM9x0gU/edit?gid="&XLOOKUP(B36,ID___!A:A,ID___!B:B,"")&"#gid="&XLOOKUP(B36,ID___!A:A,ID___!B:B,"")&"&range=A1:J1","Click"))} -> Click | B36: =IFERROR(__xludf.DUMMYFUNCTION("""COMPUTED_VALUE"""),"EHQ") -> EHQ | C36: =IFERROR(__xludf.DUMMYFUNCTION("""COMPUTED_VALUE"""),"Ehtashamul Haque") -> Ehtashamul Haque | D36: =IFERROR(__xludf.DUMMYFUNCTION("""COMPUTED_VALUE"""),"Lecturer") -> Lecturer | E36: =IFERROR(__xludf.DUMMYFUNCTION("""COMPUTED_VALUE"""),"Full Time") -> Full Time | F36: =IFERROR(__xludf.DUMMYFUNCTION("""COMPUTED_VALUE"""),"4N168") -> 4N168 | G36: =IFERROR(__xludf.DUMMYFUNCTION("""COMPUTED_VALUE"""),"ehtashamul.haque@bracu.ac.bd") -> ehtashamul.haque@bracu.ac.bd
A37: {=IF(ISBLANK(B37),,HYPERLINK("https://docs.google.com/spreadsheets/d/1aZ_8do2w3aA382MhZyJKG5amXZ6fpthJYoLsdM9x0gU/edit?gid="&XLOOKUP(B37,ID___!A:A,ID___!B:B,"")&"#gid="&XLOOKUP(B37,ID___!A:A,ID___!B:B,"")&"&range=A1:J1","Click"))} -> Click | B37: =IFERROR(__xludf.DUMMYFUNCTION("""COMPUTED_VALUE"""),"FARS") -> FARS | C37: =IFERROR(__xludf.DUMMYFUNCTION("""COMPUTED_VALUE"""),"Ahmad Farhan Shahriar Chowdhury") -> Ahmad Farhan Shahriar Chowdhury | D37: =IFERROR(__xludf.DUMMYFUNCTION("""COMPUTED_VALUE"""),"Lecturer") -> Lecturer | E37: =IFERROR(__xludf.DUMMYFUNCTION("""COMPUTED_VALUE"""),"Full Time") -> Full Time | F37: =IFERROR(__xludf.DUMMYFUNCTION("""COMPUTED_VALUE"""),"4N145") -> 4N145 | G37: =IFERROR(__xludf.DUMMYFUNCTION("""COMPUTED_VALUE"""),"farhan.shahriar@bracu.ac.bd") -> farhan.shahriar@bracu.ac.bd
A38: {=IF(ISBLANK(B38),,HYPERLINK("https://docs.google.com/spreadsheets/d/1aZ_8do2w3aA382MhZyJKG5amXZ6fpthJYoLsdM9x0gU/edit?gid="&XLOOKUP(B38,ID___!A:A,ID___!B:B,"")&"#gid="&XLOOKUP(B38,ID___!A:A,ID___!B:B,"")&"&range=A1:J1","Click"))} -> Click | B38: =IFERROR(__xludf.DUMMYFUNCTION("""COMPUTED_VALUE"""),"FBAW") -> FBAW | C38: =IFERROR(__xludf.DUMMYFUNCTION("""COMPUTED_VALUE"""),"Faria Binta Awal") -> Faria Binta Awal | D38: =IFERROR(__xludf.DUMMYFUNCTION("""COMPUTED_VALUE"""),"Lecturer") -> Lecturer | E38: =IFERROR(__xludf.DUMMYFUNCTION("""COMPUTED_VALUE"""),"Full Time") -> Full Time | F38: =IFERROR(__xludf.DUMMYFUNCTION("""COMPUTED_VALUE"""),"4K84") -> 4K84 | G38: =IFERROR(__xludf.DUMMYFUNCTION("""COMPUTED_VALUE"""),"faria.awal@bracu.ac.bd") -> faria.awal@bracu.ac.bd
